<?xml version="1.0" ?>
<robot name="car" xmlns:xacro="http://www.ros.org/wiki/xacro">

<xacro:include filename="$(find car_description)/urdf/materials.xacro" />
<xacro:include filename="$(find car_description)/urdf/car.trans" />
<xacro:include filename="$(find car_description)/urdf/car.gazebo" />
<link name="base_link">
  <inertial>
    <origin xyz="-4.347188282745399e-17 -2.1996772710691717e-14 0.28782290289670287" rpy="0 0 0"/>
    <mass value="1681.7496126748006"/>
    <inertia ixx="177.464322" iyy="70.213838" izz="147.057999" ixy="-0.0" iyz="-0.0" ixz="-0.0"/>
  </inertial>
  <visual>
    <origin xyz="0 0 0" rpy="0 0 0"/>
    <geometry>
      <mesh filename="file://$(find car_description)/meshes/base_link.stl" scale="0.001 0.001 0.001"/>
    </geometry>
    <material name="silver"/>
  </visual>
  <collision>
    <origin xyz="0 0 0" rpy="0 0 0"/>
    <geometry>
      <mesh filename="file://$(find car_description)/meshes/base_link.stl" scale="0.001 0.001 0.001"/>
    </geometry>
  </collision>
</link>

<link name="back_left_wheel_1">
  <inertial>
    <origin xyz="-0.02497879178447024 0.0 0.0010403336137875877" rpy="0 0 0"/>
    <mass value="27.74419012201489"/>
    <inertia ixx="0.311862" iyy="0.161841" izz="0.162102" ixy="0.0" iyz="0.0" ixz="-0.006251"/>
  </inertial>
  <visual>
    <origin xyz="0.227892 0.3 -0.051206" rpy="0 0 0"/>
    <geometry>
      <mesh filename="file://$(find car_description)/meshes/back_left_wheel_1.stl" scale="0.001 0.001 0.001"/>
    </geometry>
    <material name="silver"/>
  </visual>
  <collision>
    <origin xyz="0.227892 0.3 -0.051206" rpy="0 0 0"/>
    <geometry>
      <mesh filename="file://$(find car_description)/meshes/back_left_wheel_1.stl" scale="0.001 0.001 0.001"/>
    </geometry>
  </collision>
</link>

<link name="back_right_wheel_1">
  <inertial>
    <origin xyz="0.024978791784470183 5.551115123125783e-17 0.0010403336137875946" rpy="0 0 0"/>
    <mass value="27.744190122014896"/>
    <inertia ixx="0.311862" iyy="0.161841" izz="0.162102" ixy="0.0" iyz="0.0" ixz="0.006251"/>
  </inertial>
  <visual>
    <origin xyz="-0.227892 0.3 -0.051206" rpy="0 0 0"/>
    <geometry>
      <mesh filename="file://$(find car_description)/meshes/back_right_wheel_1.stl" scale="0.001 0.001 0.001"/>
    </geometry>
    <material name="silver"/>
  </visual>
  <collision>
    <origin xyz="-0.227892 0.3 -0.051206" rpy="0 0 0"/>
    <geometry>
      <mesh filename="file://$(find car_description)/meshes/back_right_wheel_1.stl" scale="0.001 0.001 0.001"/>
    </geometry>
  </collision>
</link>

<link name="front_left_wheel_1">
  <inertial>
    <origin xyz="-0.02497879178447024 5.551115123125783e-17 0.0010403336137876015" rpy="0 0 0"/>
    <mass value="27.7441901220149"/>
    <inertia ixx="0.311862" iyy="0.161841" izz="0.162102" ixy="0.0" iyz="-0.0" ixz="-0.006251"/>
  </inertial>
  <visual>
    <origin xyz="0.227892 -0.3 -0.051206" rpy="0 0 0"/>
    <geometry>
      <mesh filename="file://$(find car_description)/meshes/front_left_wheel_1.stl" scale="0.001 0.001 0.001"/>
    </geometry>
    <material name="silver"/>
  </visual>
  <collision>
    <origin xyz="0.227892 -0.3 -0.051206" rpy="0 0 0"/>
    <geometry>
      <mesh filename="file://$(find car_description)/meshes/front_left_wheel_1.stl" scale="0.001 0.001 0.001"/>
    </geometry>
  </collision>
</link>

<link name="front_right_wheel_1">
  <inertial>
    <origin xyz="0.02497879178447024 5.551115123125783e-17 0.0010403336137875946" rpy="0 0 0"/>
    <mass value="27.744190122014906"/>
    <inertia ixx="0.311862" iyy="0.161841" izz="0.162102" ixy="0.0" iyz="0.0" ixz="0.006251"/>
  </inertial>
  <visual>
    <origin xyz="-0.227892 -0.3 -0.051206" rpy="0 0 0"/>
    <geometry>
      <mesh filename="file://$(find car_description)/meshes/front_right_wheel_1.stl" scale="0.001 0.001 0.001"/>
    </geometry>
    <material name="silver"/>
  </visual>
  <collision>
    <origin xyz="-0.227892 -0.3 -0.051206" rpy="0 0 0"/>
    <geometry>
      <mesh filename="file://$(find car_description)/meshes/front_right_wheel_1.stl" scale="0.001 0.001 0.001"/>
    </geometry>
  </collision>
</link>

<joint name="back_left_wheel_to_base_link" type="continuous">
  <origin xyz="-0.227892 -0.3 0.051206" rpy="0 0 0"/>
  <parent link="base_link"/>
  <child link="back_left_wheel_1"/>
  <axis xyz="-0.999133 0.0 0.041631"/>
</joint>

<joint name="right_left_wheel_to_base_footprint" type="continuous">
  <origin xyz="0.227892 -0.3 0.051206" rpy="0 0 0"/>
  <parent link="base_link"/>
  <child link="back_right_wheel_1"/>
  <axis xyz="0.999133 0.0 0.041631"/>
</joint>

<joint name="front_left_wheel_to_base_footprint" type="continuous">
  <origin xyz="-0.227892 0.3 0.051206" rpy="0 0 0"/>
  <parent link="base_link"/>
  <child link="front_left_wheel_1"/>
  <axis xyz="-0.999133 0.0 0.041631"/>
</joint>

<joint name="front_right_wheel_to_base_footprint" type="continuous">
  <origin xyz="0.227892 0.3 0.051206" rpy="0 0 0"/>
  <parent link="base_link"/>
  <child link="front_right_wheel_1"/>
  <axis xyz="0.999133 0.0 0.041631"/>
</joint>

</robot>
